<?xml version="1.0" ?>
<sdf version="1.9">
  <model name='amazebot'>

  	<!-- Robot Footprint -->
  	<link name="base_footprint">
      <pose>0.0 0.0 0.0 0 0 0</pose>
    </link>

		<!-- base link -->
    <link name='base_link'>
      <pose>0.0 0.0 0.092 0 -0 0</pose>
      <inertial>
        <mass>0.2</mass>
        <inertia>
          <ixx>0.0122666</ixx>
          <ixy>0</ixy>
          <ixz>0</ixz>
          <iyy>0.0122666</iyy>
          <iyz>0</iyz>
          <izz>0.02</izz>
      	</inertia>
      </inertial>
      <visual name='visual_basic_link'>
        <geometry>
          <cylinder>
						<length>0.12</length>
						<radius>0.10</radius>
					</cylinder> 
        </geometry>
        <material>
          <ambient>0.5 0.5 1.0 1</ambient>
          <diffuse>0.5 0.5 1.0 1</diffuse>
          <specular>0.0 0.0 1.0 1</specular>
        </material>
      </visual>
      <collision name='collision_basic_link'>
        <geometry>
					<cylinder>
						<length>0.12</length>
						<radius>0.10</radius>
					</cylinder>
        </geometry>
      </collision>
    </link>

		<!-- left wheel link -->
    <link name='left_wheel_link'>
      <pose>-0.02 0.10 0.032 -1.5707963267948966 0 0</pose>
      <inertial>
        <mass>0.2</mass>
        <inertia>
          <ixx>0.000190416666667</ixx>
          <ixy>0</ixy>
          <ixz>0</ixz>
          <iyy>0.0001904</iyy>
          <iyz>0</iyz>
          <izz>0.00036</izz>
        </inertia>
      </inertial>
      <visual name='visual_left_wheel_link'>
        <geometry>
					<cylinder>
						<length>0.04</length>
						<radius>0.032</radius>
					</cylinder>
        </geometry>
        <material>
          <ambient>0.2 0.2 0.2 1</ambient>
          <diffuse>0.2 0.2 0.2 1</diffuse>
          <specular>0.2 0.2 0.2 1</specular>
        </material>
      </visual>
      <collision name='collision_left_wheel_link'>
        <geometry>
					<cylinder>
						<length>0.04</length>
						<radius>0.032</radius>
					</cylinder>
        </geometry>
      </collision>
    </link>

		<!-- right wheel link -->
    <link name='right_wheel_link'>
      <pose>-0.02 -0.10 0.032 -1.5707963267948966 0 0</pose>
      <inertial>
        <mass>0.2</mass>
        <inertia>
          <ixx>0.000190416666667</ixx>
          <ixy>0</ixy>
          <ixz>0</ixz>
          <iyy>0.0001904</iyy>
          <iyz>0</iyz>
          <izz>0.00036</izz>
        </inertia>
      </inertial>
      <visual name='visual_right_wheel_link'>
        <geometry>
					<cylinder>
						<length>0.04</length>
						<radius>0.032</radius>
					</cylinder>
        </geometry>
        <material>
          <ambient>0.2 0.2 0.2 1</ambient>
          <diffuse>0.2 0.2 0.2 1</diffuse>
          <specular>0.2 0.2 0.2 1</specular>
        </material>
      </visual>
      <collision name='collision_right_wheel_link'>
        <geometry>
					<cylinder>
						<length>0.04</length>
						<radius>0.032</radius>
					</cylinder>
        </geometry>
      </collision>
    </link>

		<!-- caster link -->
    <link name='caster_link'>
      <pose>0.06 0.0 0.016 0 -0 0</pose>
      <inertial>
        <mass>0.02</mass>
        <inertia>
          <ixx>0.000190416666667</ixx>
          <ixy>0</ixy>
          <ixz>0</ixz>
          <iyy>0.0001904</iyy>
          <iyz>0</iyz>
          <izz>0.00036</izz>
        </inertia>
      </inertial>
      <visual name='visual_caster_links'>
        <geometry>
          <sphere>
            <radius>0.016</radius>
          </sphere>
        </geometry>
        <material>
          <ambient>0.2 0.2 0.2 1</ambient>
          <diffuse>0.2 0.2 0.2 1</diffuse>
          <specular>0.2 0.2 0.2 1</specular>
        </material>
      </visual>
      <collision name='collision_caster_link'>
        <geometry>
          <sphere>
            <radius>0.016</radius>
          </sphere>
        </geometry>
      </collision>
    </link>

		<!-- imu link -->
    <link name='imu_link'>
      <pose>0.0 0.0 0.112 0 0 0</pose>
      <inertial>
        <mass>0.1</mass>
        <inertia>
          <ixx>0.000190416666667</ixx>
          <ixy>0</ixy>
          <ixz>0</ixz>
          <iyy>0.0001904</iyy>
          <iyz>0</iyz>
          <izz>0.00036</izz>
        </inertia>
      </inertial>
      <visual name='visual_imu_link'>
        <geometry>
					<box>
						<size>0.02 0.02 0.02</size>
					</box>
        </geometry>
        <material>
          <ambient>0.2 0.2 0.2 1</ambient>
          <diffuse>0.2 0.2 0.2 1</diffuse>
          <specular>0.2 0.2 0.2 1</specular>
        </material>
      </visual>
      <collision name='collision_imu_link'>
        <geometry>
					<box>
						<size>0.02 0.02 0.02</size>
					</box>
        </geometry>
      </collision>


    	<sensor name="imu_sensor" type="imu">
    		<plugin filename="ignition-gazebo-imu-system" name="ignition::gazebo::systems::Imu">
    			<initial_orientation_as_reference>false</initial_orientation_as_reference>
    		</plugin>
    		<topic>imu</topic>
    		<always_on>true</always_on>
    		<update_rate>100.0</update_rate>
    		<visualize>true</visualize>
    		<imu>
      		<angular_velocity>
      		  <x>
      		    <noise type="gaussian">
      		      <mean>0.0</mean>
      		      <stddev>2e-4</stddev>
      		      <bias_mean>0.0000075</bias_mean>
      		      <bias_stddev>0.0000008</bias_stddev>
      		    </noise>
      		  </x>
      		  <y>
      		    <noise type="gaussian">
      		      <mean>0.0</mean>
      		      <stddev>2e-4</stddev>
      		      <bias_mean>0.0000075</bias_mean>
      		      <bias_stddev>0.0000008</bias_stddev>
      		    </noise>
      		  </y>
      		  <z>
      		    <noise type="gaussian">
      		      <mean>0.0</mean>
      		      <stddev>2e-4</stddev>
      		      <bias_mean>0.0000075</bias_mean>
      		      <bias_stddev>0.0000008</bias_stddev>
      		    </noise>
      		  </z>
      		</angular_velocity>
      		<linear_acceleration>
      		  <x>
      		    <noise type="gaussian">
      		      <mean>0.0</mean>
      		      <stddev>1.7e-2</stddev>
      		      <bias_mean>0.01</bias_mean>
      		      <bias_stddev>0.001</bias_stddev>
      		    </noise>
      		  </x>
      		  <y>
      		    <noise type="gaussian">
      		      <mean>0.0</mean>
      		      <stddev>1.7e-2</stddev>
      		      <bias_mean>0.01</bias_mean>
      		      <bias_stddev>0.001</bias_stddev>
      		    </noise>
      		  </y>
      		  <z>
      		    <noise type="gaussian">
      		      <mean>0.0</mean>
      		      <stddev>1.7e-2</stddev>
      		      <bias_mean>0.01</bias_mean>
      		      <bias_stddev>0.001</bias_stddev>
      		    </noise>
      		  </z>
      		</linear_acceleration>
    		</imu>
    	</sensor>
    
    </link>

		<!-- lidar link -->
		<link name='lidar_link'>
      <pose>0.0 0.0 0.167 0 0 0</pose>
      <inertial>
        <mass>0.1</mass>
        <inertia>
          <ixx>0.000190416666667</ixx>
          <ixy>0</ixy>
          <ixz>0</ixz>
          <iyy>0.0001904</iyy>
          <iyz>0</iyz>
          <izz>0.00036</izz>
        </inertia>
      </inertial>
      <visual name='visual_lidar_link'>
        <geometry>
					<cylinder>
						<length>0.02</length>
						<radius>0.02</radius>
					</cylinder>
				</geometry>
        <material>
					<ambient>0.2 0.2 0.2 1</ambient>
					<diffuse>0.2 0.2 0.2 1</diffuse>
					<specular>0.2 0.2 0.2 1</specular>
				</material>
      </visual>
      <collision name='collision_lidar_link'>
        <geometry>
					<cylinder>
						<length>0.02</length>
						<radius>0.02</radius>
					</cylinder>
				</geometry>
      </collision>

      <sensor name='lidar_sensor' type='gpu_lidar'>
        <pose>0 0 0 0 0 0</pose>
        <topic>lidar</topic>
        <update_rate>10</update_rate>
        <lidar>
          <scan>
            <horizontal>
              <samples>640</samples>
              <resolution>1</resolution>
              <min_angle>-1.396263</min_angle>
              <max_angle>1.396263</max_angle>
            </horizontal>
            <vertical>
              <samples>1</samples>
              <resolution>1</resolution>
              <min_angle>0.0</min_angle>
              <max_angle>0.0</max_angle>
            </vertical>
          </scan>
          <range>
            <min>0.08</min>
            <max>10.0</max>
            <resolution>0.01</resolution>
          </range>
        </lidar>
        <visualize>true</visualize>
      </sensor>

    </link>


		<!-- base joint -->
  	<joint name="base_joint" type="fixed">
  	  <parent>base_footprint</parent>
  	  <child>base_link</child>
  	</joint>

		<!-- left wheel joint -->
    <joint name='left_wheel_joint' type='revolute'>
      <parent>base_link</parent>
      <child>left_wheel_link</child>
			<axis>
        <xyz>0 0 1</xyz>
        <limit>
          <lower>-1.79769e+308</lower>
          <upper>1.79769e+308</upper>
        </limit>
      </axis>
    </joint>

		<!-- right wheel joint -->
    <joint name='right_wheel_joint' type='revolute'>
      <parent>base_link</parent>
      <child>right_wheel_link</child>
			<axis>
        <xyz>0 0 1</xyz>
        <limit>
          <lower>-1.79769e+308</lower>
          <upper>1.79769e+308</upper>
        </limit>
      </axis>
    </joint>

		<!-- caster joint -->
    <joint name='caster_joint' type='fixed'>
      <parent>base_link</parent>
      <child>caster_link</child>
    </joint>

		<!-- imu joint -->
    <joint name='imu_joint' type='fixed'>
      <parent>base_link</parent>
      <child>imu_link</child>
		</joint>

		<!-- lidar joint -->
		<joint name='lidar_joint' type='fixed'>
      <parent>base_link</parent>
      <child>lidar_link</child>
		</joint>

    <plugin
      filename="ignition-gazebo-diff-drive-system"
      name="ignition::gazebo::systems::DiffDrive">
      <left_joint>left_wheel_joint</left_joint>
      <right_joint>right_wheel_joint</right_joint>
      <wheel_separation>0.20</wheel_separation>
      <wheel_radius>0.032</wheel_radius>
      <odom_publish_frequency>1</odom_publish_frequency>
      <max_linear_acceleration>1</max_linear_acceleration>
      <min_linear_acceleration>-1</min_linear_acceleration>
      <max_angular_acceleration>2</max_angular_acceleration>
      <min_angular_acceleration>-2</min_angular_acceleration>
      <max_linear_velocity>1.5</max_linear_velocity>
      <min_linear_velocity>-1.5</min_linear_velocity>
      <max_angular_velocity>1</max_angular_velocity>
      <min_angular_velocity>-1</min_angular_velocity>
    </plugin>

    </model>
</sdf>